Workbook

Sheet Portada
A1: SERVICIO NACIONAL DE APRENDIZAJE · SENA
A3: Formato de seguimiento de casos de prueba ejecutados
A4: Proyecto Pastoreando · Tecnólogo en Análisis y Desarrollo de Software · Ficha 3134556
A6: Evidencia | B6: GA9-220501096-AA3-EV01 · Documentación de las pruebas ejecutadas
A7: Actividad | B7: GA9-220501096-AA3 · Documentar y realizar pruebas
A8: Autor | B8: Brayian Jhovany Piedrahita Cortes
A9: Instructor | B9: Diego Fernando Henao Rojas
A10: Centro | B10: Centro de Desarrollo Agropecuario · Regional Risaralda
A11: Fecha de elaboración | B11: 26 de octubre de 2026
A12: Repositorio | B12: https://github.com/brayian-piedrahita/pastoreando-software (etiqueta ga9-aa3-ev01)
A14: Estado de los casos (se calcula solo)
A15: Casos diseñados | B15: =COUNTA('Casos de prueba'!$A$5:$A$200) -> 59
A16: Casos críticos | B16: =COUNTIF('Casos de prueba'!$G$5:$G$200,"Crítica") -> 15
A17: Aprobados | B17: =COUNTIF('Casos de prueba'!$Q$5:$Q$200,"Aprobado") -> 55
A18: En seguimiento | B18: =COUNTIF('Casos de prueba'!$Q$5:$Q$200,"En seguimiento") -> 0
A19: Rechazados | B19: =COUNTIF('Casos de prueba'!$Q$5:$Q$200,"Rechazado") -> 0
A20: Sin ejecutar | B20: =B15-B17-B18-B19 -> 4
A21: Avance de ejecución | B21: =IF(B15=0,0,(B17+B18+B19)/B15) -> 0.93220339
A22: Requisitos sin ningún caso | B22: =Trazabilidad!D20 -> 0
A24: Contenido del libro
A25: Casos de prueba | B25: Los casos con los campos del formato: proyecto, nombre, fecha de revisión, descripción, ambiente, herramienta, autor, número, salida esperada, salida obtenida, resultado, seguimiento, severidad, evidencia y firma de aprobación.
A26: Ficha de caso | B26: Vista de un caso por número, lista para imprimir o guardar en PDF.
A27: Ambiente de pruebas | B27: Ambientes, software, hardware, datos y usuarios de prueba, diferencias con producción y cobertura por ambiente.
A28: Trazabilidad | B28: Requisitos contra casos y resultados, con la cobertura de cada uno.
A30: Cómo se diligencia
A31: Paso 1 | B31: El número de caso es consecutivo (CP-001, CP-002...) y no se reutiliza.
A32: Paso 2 | B32: Las columnas con fondo amarillo (fecha de revisión, salida obtenida, resultado, seguimiento, severidad, evidencia y firma) se llenan al ejecutar cada caso.
A33: Paso 3 | B33: Resultado: Aprobado, En seguimiento o Rechazado. Si no fue el esperado, se anota en Seguimiento el código del defecto (DEF-001...) y la severidad Alta, Media o Baja.
A34: Paso 4 | B34: La evidencia es la ruta de la captura, del archivo de resultados o de la salida de consola que respalda el resultado.
A35: Paso 5 | B35: Los casos marcados como pendientes de construir se ejecutan cuando exista la funcionalidad; hasta entonces quedan sin ejecutar.
A36: Paso 6 | B36: El caso CP-001 sirve de ejemplo de un caso aprobado a la primera; el CP-007 muestra un defecto (DEF-001) corregido y el caso repetido.

Sheet Casos de prueba
A1: Formato de casos de prueba · Pastoreando
A2: Los casos se diseñan antes de ejecutar las pruebas. Las columnas con fondo amarillo se diligencian durante la ejecución; el caso 001 ya está ejecutado y sirve de ejemplo del diligenciamiento.
A3: DISEÑO DEL CASO | O3: EJECUCIÓN Y REGISTRO
A4: N° de caso | B4: Nombre del proyecto | C4: Nombre del caso de prueba | D4: Requisito | E4: Módulo | F4: Tipo de prueba | G4: Prioridad | H4: Descripción del caso de prueba | I4: Ambiente o entorno de prueba | J4: Herramienta utilizada | K4: Prueba automatizada asociada | L4: Autor del caso de prueba | M4: Precondiciones y datos de entrada | N4: Salida esperada | O4: Fecha de revisión | P4: Salida obtenida | Q4: Resultado | R4: Seguimiento | S4: Severidad | T4: Evidencia | U4: Firma de aprobación
A5: CP-001 | B5: Pastoreando | C5: Cálculo del costo por cabeza con propósito Carne | D5: RF01 | E5: Costos por unidad ganadera | F5: Funcional | G5: Crítica | H5: Prueba funcional del servicio de cálculo, ejecutada con JMeter: con costos conocidos y 50 animales de carne, el costo final por cabeza debe seguir las reglas de negocio (factor 1,00 y margen del 20 %) y la respuesta debe traer el desglose por rubro. | I5: E6 · API: Postman y Apache JMeter 5.6.3 contra la API local con SQLite de pruebas | J5: Apache JMeter | K5: docs/pruebas/jmeter/pastoreando_carga_basica.jmx | L5: Brayian Jhovany Piedrahita Cortes | M5: API en ejecución; usuario Contador de demostración con sesión iniciada. POST /api/costos/calcular con alimentación 6.000.000, mantenimiento 3.000.000, servicios 1.500.000, impuestos 1.500.000, 50 animales y propósito Carne. | N5: Código 200; subtotal 12.000.000; costo base por cabeza 240.000; margen 48.000; costo unitario final 288.000; total del lote 14.400.000; desglose 50 %, 25 %, 12,5 % y 12,5 %; campo id_calculo presente; respuesta en menos de 2000 ms. | O5: 46321 | P5: Código 200 y campo id_calculo presente en las 50 ejecuciones; 0 errores; tiempo medio de 16 ms y máximo de 108 ms (límite de 2000 ms). | Q5: Aprobado | R5: Los importes los comprueba pytest (CP-004); el plan de JMeter valida código, id_calculo y tiempo. | S5: No aplica | T5: ejecucion/jmeter_20261026.jtl y captura del resumen de la terminal (250 muestras, 0 errores) en el informe EV01. | U5: Brayian Jhovany Piedrahita Cortes
A6: CP-002 | B6: Pastoreando | C6: Cálculo del costo por cabeza con propósito Leche | D6: RF01 | E6: Costos por unidad ganadera | F6: Funcional | G6: Crítica | H6: Prueba funcional de la estrategia de ganado de leche con los mismos costos del caso 001: comprueba que el factor 1,10 se aplique antes del margen del 20 %. | I6: E3 · Backend: pytest con Python 3.13 y SQLite temporal por prueba | J6: pytest | K6: tests/test_ga9_limites.py (CP-002-leche) y tests/test_dominio.py | L6: Brayian Jhovany Piedrahita Cortes | M6: Mismos datos del caso 001 con propósito Leche. Usuario Contador con sesión. | N6: Código 200; costo base 240.000; factor 1,10; margen 52.800; costo unitario final 316.800; total del lote 15.840.000. | O6: 46321 | P6: Código 200; costo base 240.000; factor 1,10; margen 52.800; costo unitario final 316.800; total del lote 15.840.000. | Q6: Aprobado | R6: Se ejecutó con pytest en lugar de Postman: misma verificación, automatizada. | S6: No aplica | T6: docs/pruebas/ejecucion/resultados/pytest_sqlite_20261026_final.log y pytest_mysql_20261026_final.log | U6: Brayian Jhovany Piedrahita Cortes
A7: CP-003 | B7: Pastoreando | C7: Cálculo del costo por cabeza con propósito Doble Propósito | D7: RF01 | E7: Costos por unidad ganadera | F7: Unitaria | G7: Crítica | H7: Prueba unitaria de la estrategia de doble propósito: verifica el factor 1,05 y el redondeo a dos decimales. | I7: E3 · Backend: pytest con Python 3.13 y SQLite temporal por prueba | J7: pytest | K7: tests/test_costos.py, tests/test_dominio.py, tests/test_ga9_limites.py | L7: Brayian Jhovany Piedrahita Cortes | M7: Mismos datos del caso 001 con propósito Doble Propósito. | N7: Costo base 240.000; factor 1,05; margen 50.400; costo unitario final 302.400; total del lote 15.120.000. | O7: 46321 | P7: Costo base 240.000; factor 1,05; margen 50.400; costo unitario final 302.400; total del lote 15.120.000. | Q7: Aprobado | R7: No aplica | S7: No aplica | T7: docs/pruebas/ejecucion/resultados/pytest_sqlite_20261026_final.log y pytest_mysql_20261026_final.log | U7: Brayian Jhovany Piedrahita Cortes
A8: CP-004 | B8: Pastoreando | C8: Desglose de costos por rubro suma 100 % | D8: RF02 | E8: Costos por unidad ganadera | F8: Unitaria | G8: Alta | H8: Prueba unitaria del desglose: con los datos del caso 001 cada rubro debe traer valor del lote, valor por cabeza y porcentaje, y los porcentajes deben sumar 100 %. | I8: E3 · Backend: pytest con Python 3.13 y SQLite temporal por prueba | J8: pytest | K8: tests/test_costos.py, tests/test_ga9_complemento.py | L8: Brayian Jhovany Piedrahita Cortes | M8: Datos del caso 001. | N8: Alimentación 50 %, mantenimiento 25 %, servicios 12,5 % e impuestos 12,5 %; suma 100 %; valor por cabeza de cada rubro coincide con su porcentaje del costo base. | O8: 46321 | P8: Alimentación 50 % (6.000.000 del lote; 120.000 por cabeza), mantenimiento 25 %, servicios 12,5 % e impuestos 12,5 %; suma 100 %; cada valor por cabeza coincide con su porcentaje de 240.000. | Q8: Aprobado | R8: No aplica | S8: No aplica | T8: docs/pruebas/ejecucion/resultados/pytest_sqlite_20261026_final.log y pytest_mysql_20261026_final.log | U8: Brayian Jhovany Piedrahita Cortes
A9: CP-005 | B9: Pastoreando | C9: Cálculo de costos con datos inválidos | D9: RF01 | E9: Costos por unidad ganadera | F9: Unitaria | G9: Alta | H9: Prueba de valores límite y de partición de equivalencia sobre la entrada del cálculo: animales en 0, negativos o con texto, todos los rubros en cero, rubros negativos y propósito inexistente. | I9: E3 · Backend: pytest con Python 3.13 y SQLite temporal por prueba | J9: pytest | K9: tests/test_costos.py, tests/test_validaciones.py, tests/test_ga9_complemento.py | L9: Brayian Jhovany Piedrahita Cortes | M9: Usuario Contador con sesión. Cada entrada inválida se envía por separado. | N9: Cada entrada se rechaza con 422 e indica el campo; ningún cálculo inválido queda en el historial. | O9: 46321 | P9: Animales en 0, negativos y con texto, cuatro rubros en 0, rubro negativo y propósito «Cerdos»: los seis responden 422 y el historial queda igual. | Q9: Aprobado | R9: No aplica | S9: No aplica | T9: docs/pruebas/ejecucion/resultados/pytest_sqlite_20261026_final.log y pytest_mysql_20261026_final.log | U9: Brayian Jhovany Piedrahita Cortes
A10: CP-006 | B10: Pastoreando | C10: Permisos del cálculo de costos por rol | D10: RF01 | E10: Costos por unidad ganadera | F10: Seguridad | G10: Alta | H10: Prueba de seguridad por rol: el Técnico no puede calcular costos; Contador, Propietario y Arrendatario sí. | I10: E3 · Backend: pytest con Python 3.13 y SQLite temporal por prueba | J10: pytest | K10: tests/test_costos.py, tests/test_ga9_limites.py | L10: Brayian Jhovany Piedrahita Cortes | M10: Un usuario de cada rol con sesión iniciada y los datos del caso 001. | N10: Técnico recibe 403; los otros tres roles reciben 200. | O10: 46321 | P10: Técnico recibe 403; Contador, Propietario y Arrendatario reciben 200. | Q10: Aprobado | R10: No aplica | S10: No aplica | T10: docs/pruebas/ejecucion/resultados/pytest_sqlite_20261026_final.log y pytest_mysql_20261026_final.log | U10: Brayian Jhovany Piedrahita Cortes
A11: CP-007 | B11: Pastoreando | C11: Desglose interactivo y formulario de costos en pantalla | D11: RF02 | E11: Costos por unidad ganadera | F11: Usabilidad | G11: Alta | H11: Prueba funcional y de usabilidad en el navegador: se diligencia el formulario, se calcula y se revisa el desglose por rubro (valor, porcentaje y vista por unidad ganadera o lote completo); luego se deja un dato inválido y se comprueba que no queda a la vista un resultado anterior. | I11: E1 · Web: Edge en Windows, interfaz Vite (localhost:5173) y API local con SQLite de pruebas | J11: Manual (Edge) | K11: Manual (Edge) y, para la regresión de DEF-001, frontend-react/src/pruebas/componentes.test.jsx y navegacion.test.jsx | L11: Brayian Jhovany Piedrahita Cortes | M11: Sesión de Contador en la pestaña de cálculo; datos del caso 001. | N11: El resultado muestra costo por cabeza y total del lote; el desglose muestra el valor de cada rubro y su porcentaje; los errores aparecen junto al campo y, mientras los datos no sean válidos, el resultado anterior no queda en pantalla. | O11: 46321 | P11: Primera ejecución: con los datos del caso 001 el resultado es $288.000 por cabeza y $14.400.000 del lote, con valor y porcentaje por rubro y vista por unidad ganadera o lote completo; con 0 animales aparecía «Debe ser mayor o igual a 1» pero el resultado anterior seguía en pantalla (DEF-001). Repetición con la corrección (commit 3f13120): calcula con 50 animales y, al dejar 0, aparece «Debe ser mayor o igual a 1», el resultado desaparece y el panel vuelve a «Ingrese los valores y presione calcular». | Q11: Aprobado | R11: DEF-001 (severidad Baja) corregido y verificado el 26-oct-2026; la regresión de la interfaz queda en 161 de 161 pruebas. Ajuste al diseño del caso: la web muestra el desglose siempre visible y el despliegue al tocar un rubro es de la app móvil, por eso se corrigió el texto del caso. | S11: Baja | T11: Capturas del módulo contable (unidad, lote, error y repetición) en el informe EV01 y docs/pruebas/ejecucion/resultados/vitest_20261026_correccion.log | U11: Brayian Jhovany Piedrahita Cortes
A12: CP-008 | B12: Pastoreando | C12: Registro de un Propietario con datos válidos | D12: Acceso | E12: Acceso y sesión | F12: Funcional | G12: Crítica | H12: Prueba funcional del registro en el navegador: se completa el formulario con datos válidos y luego se inicia sesión con el usuario creado. | I12: E1 · Web: Edge en Windows, interfaz Vite (localhost:5173) y API local con SQLite de pruebas | J12: Manual (Edge) | K12: tests/test_registro.py (equivalente automático) | L12: Brayian Jhovany Piedrahita Cortes | M12: Correo y cédula que no existan en la base; nombre y apellidos solo letras; cédula de 10 dígitos; contraseña de 8 a 72 caracteres con letras y números. | N12: Respuesta 201 con el mensaje «Usuario registrado correctamente» y sin la contraseña; el usuario puede iniciar sesión. | O12: 46321 | P12: Se registra «Ana María Soto Peña» como Propietario; la pantalla muestra «Registro exitoso. Ahora puede iniciar sesión.» y el inicio de sesión con el usuario nuevo abre el panel con el rol Propietario. | Q12: Aprobado | R12: La interfaz no muestra el texto de la API; el 201 y la ausencia de contraseña los verifica Postman. | S12: No aplica | T12: Capturas del formulario de registro, del mensaje y del panel en el informe EV01. | U12: Brayian Jhovany Piedrahita Cortes
A13: CP-009 | B13: Pastoreando | C13: Registro con correo o cédula repetidos | D13: Acceso | E13: Acceso y sesión | F13: Funcional | G13: Alta | H13: Prueba funcional del control de unicidad: se intenta registrar un usuario con un correo existente y otro con una cédula existente. | I13: E3 · Backend: pytest con Python 3.13 y SQLite temporal por prueba | J13: pytest | K13: tests/test_registro.py | L13: Brayian Jhovany Piedrahita Cortes | M13: Usuario de demostración ya registrado. | N13: Ambos intentos responden 409 y no se crea ningún usuario. | O13: 46321 | P13: Correo repetido y cédula repetida responden 409; no se crea ningún usuario. | Q13: Aprobado | R13: No aplica | S13: No aplica | T13: docs/pruebas/ejecucion/resultados/pytest_sqlite_20261026_final.log y pytest_mysql_20261026_final.log | U13: Brayian Jhovany Piedrahita Cortes
A14: CP-010 | B14: Pastoreando | C14: Registro de Técnico o Contador sin código de profesional | D14: Acceso | E14: Acceso y sesión | F14: Funcional | G14: Alta | H14: Prueba funcional de la regla de registro profesional: Técnico y Contador deben presentar el código de profesional definido en el servidor. | I14: E3 · Backend: pytest con Python 3.13 y SQLite temporal por prueba | J14: pytest | K14: tests/test_registro.py | L14: Brayian Jhovany Piedrahita Cortes | M14: Datos válidos de Técnico y de Contador, primero sin el código y luego con un código incorrecto. | N14: El registro se rechaza y no se crea el usuario; Propietario y Arrendatario no requieren código. | O14: 46321 | P14: Técnico y Contador sin código o con código incorrecto son rechazados; Propietario y Arrendatario se registran sin código. | Q14: Aprobado | R14: El Contador no se probó por separado del Técnico. | S14: No aplica | T14: docs/pruebas/ejecucion/resultados/pytest_sqlite_20261026_final.log y pytest_mysql_20261026_final.log | U14: Brayian Jhovany Piedrahita Cortes
A15: CP-011 | B15: Pastoreando | C15: Valores límite de cédula y contraseña | D15: Acceso | E15: Acceso y sesión | F15: Unitaria | G15: Alta | H15: Prueba de análisis de valores límite: cédula con 5, 6, 12 y 13 dígitos y con letras; contraseña con 7, 8, 72 y 73 caracteres, solo letras y solo números. | I15: E3 · Backend: pytest con Python 3.13 y SQLite temporal por prueba | J15: pytest | K15: tests/test_registro.py, tests/test_validaciones.py, tests/test_ga9_limites.py | L15: Brayian Jhovany Piedrahita Cortes | M15: Resto de campos válidos. Cada valor se prueba por separado. | N15: Se aceptan 6 y 12 dígitos y contraseñas de 8 y 72 caracteres con letras y números; los demás se rechazan con 422 y el nombre del campo. | O15: 46321 | P15: Cédulas de 6 y 12 dígitos aceptadas; 5, 13 y con letras rechazadas. Contraseñas de 8 y 72 caracteres con letras y números aceptadas; 7, 73, solo letras y solo números rechazadas con 422 y el campo. | Q15: Aprobado | R15: No aplica | S15: No aplica | T15: docs/pruebas/ejecucion/resultados/pytest_sqlite_20261026_final.log y pytest_mysql_20261026_final.log | U15: Brayian Jhovany Piedrahita Cortes
A16: CP-012 | B16: Pastoreando | C16: Inicio de sesión correcto con token y rol | D16: Acceso | E16: Acceso y sesión | F16: Funcional | G16: Crítica | H16: Prueba funcional de la API con Postman: se inicia sesión con los cuatro roles de demostración y se consulta GET /api/auth/yo con el token. | I16: E6 · API: Postman y Apache JMeter 5.6.3 contra la API local con SQLite de pruebas | J16: Postman | K16: Pastoreando_AA5_EV04.postman_collection.json | L16: Brayian Jhovany Piedrahita Cortes | M16: Usuarios de demostración de cada rol (ver hoja Ambiente de pruebas). | N16: Código 200 con token, tipo y usuario; /api/auth/yo devuelve id_usuario, rol y nombre del usuario que inició sesión. | O16: 46321 | P16: Los cuatro inicios de sesión (Propietario, Arrendatario, Técnico y Contador) responden 200 con token JWT de tres partes; GET /api/auth/yo con el token del Propietario responde 200 y devuelve el rol Propietario. | Q16: Aprobado | R16: La colección usa usuarios nuevos y /yo se probó solo con el Propietario. | S16: No aplica | T16: Captura del resumen del Runner de Postman del 26-oct-2026 (136 verificaciones, 0 fallidas) en el informe EV01. | U16: Brayian Jhovany Piedrahita Cortes
... A59: CP-055 | B59: Pastoreando | C59: Suite de pruebas unitarias de la aplicación Android | D59: Transversal | E59: Aplicación móvil Android | F59: Regresión | G59: Media | H59: Prueba de regresión: se ejecutan las pruebas de JUnit del módulo de la aplicación móvil. | I59: E8 · Android: JUnit y aplicación en emulador o dispositivo | J59: JUnit | K59: 89 pruebas JUnit del proyecto Android | L59: Brayian Jhovany Piedrahita Cortes | M59: Proyecto Android abierto en Android Studio. | N59: Las 89 pruebas terminan aprobadas. | O59: 46321 | P59: 89 pruebas en 11 clases: 0 omitidas, 0 fallos y 0 errores; BUILD SUCCESSFUL en 17 s. | Q59: Aprobado | R59: Se ejecutó con Gradle desde la terminal (tarea testDebugUnitTest) y no desde Android Studio. | S59: No aplica | T59: Captura de la terminal con BUILD SUCCESSFUL y el total de 89 pruebas en el informe EV01; resultados en app/build/test-results/testDebugUnitTest. | U59: Brayian Jhovany Piedrahita Cortes
A60: CP-056 | B60: Pastoreando | C60: Área de un lote a partir de su perímetro | D60: RF07 | E60: Parcelación de lotes (pendiente) | F60: Unitaria | G60: Media | H60: Prueba unitaria del cálculo de área con polígonos de área conocida y valores límite. | I60: E3 · Backend: pytest con Python 3.13 y SQLite temporal por prueba | J60: pytest | K60: Por crear junto con la funcionalidad | L60: Brayian Jhovany Piedrahita Cortes | M60: PENDIENTE DE CONSTRUIR. Requiere RF07 construido. Rectángulo de 100 × 50 metros, triángulo rectángulo de catetos 30 y 40, polígono de 2 vértices y vértices repetidos. | N60: Rectángulo 5.000 m² (0,5 ha); triángulo 600 m²; el polígono de 2 vértices y los vértices repetidos se rechazan.
A61: CP-057 | B61: Pastoreando | C61: Alarma al cruzar el umbral configurado | D61: RF08 | E61: Alarmas (pendiente) | F61: Integración | G61: Media | H61: Prueba de integración del umbral de alarma con valores límite alrededor del 80 %. | I61: E1 · Web: Edge en Windows, interfaz Vite (localhost:5173) y API local con SQLite de pruebas | J61: Manual (Edge) | K61: Por crear junto con la funcionalidad | L61: Brayian Jhovany Piedrahita Cortes | M61: PENDIENTE DE CONSTRUIR. Requiere RF08 construido. Umbral configurado en 80 % y lotes con 79,9 %, 80 % y 80,1 % de carga. | N61: No se dispara con 79,9 %; se dispara con 80,1 %; el comportamiento con 80 % coincide con la regla de la alerta de carga.
A62: CP-058 | B62: Pastoreando | C62: Sincronización de cambios hechos sin conexión | D62: RNF01 | E62: Persistencia y operación sin conexión | F62: Integración | G62: Media | H62: Prueba funcional en el navegador de la sincronización completa: se registran cambios sin red y se restablece la conexión. | I62: E1 · Web: Edge en Windows, interfaz Vite (localhost:5173) y API local con SQLite de pruebas | J62: Manual (Edge) | K62: Por crear junto con la funcionalidad | L62: Brayian Jhovany Piedrahita Cortes | M62: PENDIENTE DE CONSTRUIR. Requiere la sincronización con IndexedDB. Red desconectada desde las herramientas de desarrollo; dos registros nuevos hechos sin conexión. | N62: Al volver la red los dos registros llegan al servidor una sola vez, sin pérdidas ni duplicados.
A63: CP-059 | B63: Pastoreando | C63: Copia de seguridad diaria restaurable | D63: RNF02 | E63: Respaldos (pendiente) | F63: Funcional | G63: Media | H63: Prueba de procedimiento: se genera la copia, se restaura sobre una base vacía y se comparan los conteos de las 6 tablas. | I63: E4 · Backend: pytest contra MySQL 8.4 local (base pastoreando_prueba) | J63: Manual (consola y mysqldump) | K63: Por crear junto con la funcionalidad | L63: Brayian Jhovany Piedrahita Cortes | M63: PENDIENTE DE CONSTRUIR. Requiere la programación de copias diarias. Base MySQL de pruebas con datos de demostración y una base vacía de destino. | N63: La copia se genera sin errores y, restaurada, deja las 6 tablas con los mismos conteos de filas que el origen.

Sheet Ficha de caso
A1: Ficha de caso de prueba · Pastoreando
A2: Elija el número de caso en la celda amarilla: la ficha se llena con los datos de la hoja «Casos de prueba» y queda lista para imprimir o guardar en PDF.
A3: Número de caso | B3: CP-007
A4: Nombre del proyecto | B4: =IFERROR(IF(INDEX('Casos de prueba'!$B$5:$B$200,MATCH($B$3,'Casos de prueba'!$A$5:$A$200,0))="","",INDEX('Casos de prueba'!$B$5:$B$200,MATCH($B$3,'Casos de prueba'!$A$5:$A$200,0))),"") -> Pastoreando
A5: Nombre del caso de prueba | B5: =IFERROR(IF(INDEX('Casos de prueba'!$C$5:$C$200,MATCH($B$3,'Casos de prueba'!$A$5:$A$200,0))="","",INDEX('Casos de prueba'!$C$5:$C$200,MATCH($B$3,'Casos de prueba'!$A$5:$A$200,0))),"") -> Desglose interactivo y formulario de costos en pantalla
A6: Requisito asociado | B6: =IFERROR(IF(INDEX('Casos de prueba'!$D$5:$D$200,MATCH($B$3,'Casos de prueba'!$A$5:$A$200,0))="","",INDEX('Casos de prueba'!$D$5:$D$200,MATCH($B$3,'Casos de prueba'!$A$5:$A$200,0))),"") -> RF02
A7: Módulo | B7: =IFERROR(IF(INDEX('Casos de prueba'!$E$5:$E$200,MATCH($B$3,'Casos de prueba'!$A$5:$A$200,0))="","",INDEX('Casos de prueba'!$E$5:$E$200,MATCH($B$3,'Casos de prueba'!$A$5:$A$200,0))),"") -> Costos por unidad ganadera
A8: Tipo de prueba y prioridad | B8: =IFERROR(IF(INDEX('Casos de prueba'!$F$5:$F$200,MATCH($B$3,'Casos de prueba'!$A$5:$A$200,0))="","",INDEX('Casos de prueba'!$F$5:$F$200,MATCH($B$3,'Casos de prueba'!$A$5:$A$200,0))),"")&IF(IFERROR(IF(INDEX('Casos de prueba'!$G$5:$G$200,MATCH($B$3,'Casos de prueba'!$A$5:$A$200,0))="","",INDEX('Casos de prueba'!$G$5:$G$200,MATCH($B$3,'Casos de prueba'!$A$5:$A$200,0))),"")="",""," · Prioridad "&IFERROR(IF(INDEX('Casos de prueba'!$G$5:$G$200,MATCH($B$3,'Casos de prueba'!$A$5:$A$200,0))="","",INDEX('Casos de prueba'!$G$5:$G$200,MATCH($B$3,'Casos de prueba'!$A$5:$A$200,0))),"")) -> Usabilidad · Prioridad Alta
A9: Descripción del caso de prueba | B9: =IFERROR(IF(INDEX('Casos de prueba'!$H$5:$H$200,MATCH($B$3,'Casos de prueba'!$A$5:$A$200,0))="","",INDEX('Casos de prueba'!$H$5:$H$200,MATCH($B$3,'Casos de prueba'!$A$5:$A$200,0))),"") -> Prueba funcional y de usabilidad en el navegador: se diligencia el formulario, se calcula y se revisa el desglose por rubro (valor, porcentaje y vista por unidad ganadera o lote completo); luego se deja un dato inválido y se comprueba que no queda a la vista un resultado anterior.
A10: Ambiente o entorno de prueba | B10: =IFERROR(IF(INDEX('Casos de prueba'!$I$5:$I$200,MATCH($B$3,'Casos de prueba'!$A$5:$A$200,0))="","",INDEX('Casos de prueba'!$I$5:$I$200,MATCH($B$3,'Casos de prueba'!$A$5:$A$200,0))),"") -> E1 · Web: Edge en Windows, interfaz Vite (localhost:5173) y API local con SQLite de pruebas
A11: Herramienta utilizada | B11: =IFERROR(IF(INDEX('Casos de prueba'!$J$5:$J$200,MATCH($B$3,'Casos de prueba'!$A$5:$A$200,0))="","",INDEX('Casos de prueba'!$J$5:$J$200,MATCH($B$3,'Casos de prueba'!$A$5:$A$200,0))),"") -> Manual (Edge)
A12: Prueba automatizada asociada | B12: =IFERROR(IF(INDEX('Casos de prueba'!$K$5:$K$200,MATCH($B$3,'Casos de prueba'!$A$5:$A$200,0))="","",INDEX('Casos de prueba'!$K$5:$K$200,MATCH($B$3,'Casos de prueba'!$A$5:$A$200,0))),"") -> Manual (Edge) y, para la regresión de DEF-001, frontend-react/src/pruebas/componentes.test.jsx y navegacion.test.jsx
A13: Autor del caso de prueba | B13: =IFERROR(IF(INDEX('Casos de prueba'!$L$5:$L$200,MATCH($B$3,'Casos de prueba'!$A$5:$A$200,0))="","",INDEX('Casos de prueba'!$L$5:$L$200,MATCH($B$3,'Casos de prueba'!$A$5:$A$200,0))),"") -> Brayian Jhovany Piedrahita Cortes
A14: Precondiciones y datos de entrada | B14: =IFERROR(IF(INDEX('Casos de prueba'!$M$5:$M$200,MATCH($B$3,'Casos de prueba'!$A$5:$A$200,0))="","",INDEX('Casos de prueba'!$M$5:$M$200,MATCH($B$3,'Casos de prueba'!$A$5:$A$200,0))),"") -> Sesión de Contador en la pestaña de cálculo; datos del caso 001.
A15: Salida esperada | B15: =IFERROR(IF(INDEX('Casos de prueba'!$N$5:$N$200,MATCH($B$3,'Casos de prueba'!$A$5:$A$200,0))="","",INDEX('Casos de prueba'!$N$5:$N$200,MATCH($B$3,'Casos de prueba'!$A$5:$A$200,0))),"") -> El resultado muestra costo por cabeza y total del lote; el desglose muestra el valor de cada rubro y su porcentaje; los errores aparecen junto al campo y, mientras los datos no sean válidos, el resultado anterior no queda en pantalla.
A16: Fecha de revisión | B16: =IFERROR(IF(INDEX('Casos de prueba'!$O$5:$O$200,MATCH($B$3,'Casos de prueba'!$A$5:$A$200,0))="","",TEXT(INDEX('Casos de prueba'!$O$5:$O$200,MATCH($B$3,'Casos de prueba'!$A$5:$A$200,0)),"dd/mm/yyyy")),"") -> 26/10/2026
A17: Salida obtenida | B17: =IFERROR(IF(INDEX('Casos de prueba'!$P$5:$P$200,MATCH($B$3,'Casos de prueba'!$A$5:$A$200,0))="","",INDEX('Casos de prueba'!$P$5:$P$200,MATCH($B$3,'Casos de prueba'!$A$5:$A$200,0))),"") -> Primera ejecución: con los datos del caso 001 el resultado es $288.000 por cabeza y $14.400.000 del lote, con valor y porcentaje por rubro y vista por unidad ganadera o lote completo; con 0 animales aparecía «Debe ser mayor o igual a 1» pero el resultado anterior seguía en pantalla (DEF-001). Repetición con la corrección (commit 3f13120): calcula con 50 animales y, al dejar 0, aparece «Debe ser mayor o igual a 1», el resultado desaparece y el panel vuelve a «Ingrese los valores y presione calcular».
A18: Resultado | B18: =IFERROR(IF(INDEX('Casos de prueba'!$Q$5:$Q$200,MATCH($B$3,'Casos de prueba'!$A$5:$A$200,0))="","",INDEX('Casos de prueba'!$Q$5:$Q$200,MATCH($B$3,'Casos de prueba'!$A$5:$A$200,0))),"") -> Aprobado
A19: Seguimiento | B19: =IFERROR(IF(INDEX('Casos de prueba'!$R$5:$R$200,MATCH($B$3,'Casos de prueba'!$A$5:$A$200,0))="","",INDEX('Casos de prueba'!$R$5:$R$200,MATCH($B$3,'Casos de prueba'!$A$5:$A$200,0))),"") -> DEF-001 (severidad Baja) corregido y verificado el 26-oct-2026; la regresión de la interfaz queda en 161 de 161 pruebas. Ajuste al diseño del caso: la web muestra el desglose siempre visible y el despliegue al tocar un rubro es de la app móvil, por eso se corrigió el texto del caso.
A20: Severidad | B20: =IFERROR(IF(INDEX('Casos de prueba'!$S$5:$S$200,MATCH($B$3,'Casos de prueba'!$A$5:$A$200,0))="","",INDEX('Casos de prueba'!$S$5:$S$200,MATCH($B$3,'Casos de prueba'!$A$5:$A$200,0))),"") -> Baja
A21: Evidencia | B21: =IFERROR(IF(INDEX('Casos de prueba'!$T$5:$T$200,MATCH($B$3,'Casos de prueba'!$A$5:$A$200,0))="","",INDEX('Casos de prueba'!$T$5:$T$200,MATCH($B$3,'Casos de prueba'!$A$5:$A$200,0))),"") -> Capturas del módulo contable (unidad, lote, error y repetición) en el informe EV01 y docs/pruebas/ejecucion/resultados/vitest_20261026_correccion.log
A22: Firma de aprobación | B22: =IFERROR(IF(INDEX('Casos de prueba'!$U$5:$U$200,MATCH($B$3,'Casos de prueba'!$A$5:$A$200,0))="","",INDEX('Casos de prueba'!$U$5:$U$200,MATCH($B$3,'Casos de prueba'!$A$5:$A$200,0))),"") -> Brayian Jhovany Piedrahita Cortes
A24: Las filas con fondo amarillo se llenan durante la ejecución en la hoja «Casos de prueba»; aquí solo se consultan.

Sheet Ambiente de pruebas
A1: Ambiente de pruebas · Pastoreando
A2: El ambiente de pruebas reproduce lo que importa del entorno de producción (motor de base de datos, versiones y forma de servir la aplicación) y declara las diferencias que no se pueden evitar.
A4: 1. Ambientes de prueba definidos
A5: Código | B5: Ambiente | C5: Para qué se usa | D5: Sistema operativo, navegador o dispositivo | E5: Servidor y base de datos | F5: Cuándo se usa
A6: E1 | B6: Web con API local | C6: Casos funcionales y de usabilidad en el navegador | D6: Windows 11 con Microsoft Edge | E6: Uvicorn en 127.0.0.1:8000 y Vite en localhost:5173; SQLite de pruebas (data/jmeter_prueba.db) | F6: Ejecución diaria y video de las pruebas
A7: E2 | B7: Web móvil emulada | C7: Usabilidad en pantalla de teléfono | D7: Edge con emulación de iPhone 16 (393 × 852) | E7: Igual a E1 | F7: Casos de usabilidad móvil
A8: E3 | B8: Backend con SQLite | C8: Pruebas unitarias, de integración y de seguridad de la API | D8: Windows con Git Bash; Python 3.13 | E8: Sin servidor: cliente de prueba de FastAPI; SQLite temporal por prueba | F8: Cada cambio de código
A9: E4 | B9: Backend con MySQL | C9: Paridad con producción y pruebas de la capa de datos | D9: Windows con Git Bash; Python 3.13 | E9: MySQL 8.4 local, base pastoreando_prueba (la suite se detiene si el nombre no termina en _prueba) | F9: Antes de cerrar cada etapa
A10: E5 | B10: Interfaz con Vitest | C10: Pruebas de componentes, servicios y navegación | D10: Node 24.22.1 con jsdom | E10: Sin servidor | F10: Cada cambio de la interfaz
A11: E6 | B11: API con Postman y JMeter | C11: Pruebas funcionales de servicios, de seguridad y de carga | D11: Windows; Postman; Apache JMeter 5.6.3 con Java Temurin 21 | E11: API local con SQLite de pruebas | F11: Ejecución de servicios y de carga
A12: E7 | B12: Revisión en línea | C12: Verificación final de solo lectura de la versión publicada | D12: Edge en Windows | E12: Render (plan gratuito) con MySQL 8.4 en Aiven (plan gratuito, TLS): https://pastoreando.onrender.com | F12: Recorridos cortos al cierre; sin cargas
A13: E8 | B13: Android | C13: Pruebas de la aplicación móvil | D13: Emulador o teléfono Android con la APK; Android Studio para JUnit | E13: API de Render o local, según la prueba | F13: Casos de la aplicación móvil
A15: 2. Ambiente de software
A16: Componente | B16: Versión o detalle | C16: Uso en las pruebas | D16: En producción | E16: Diferencia con producción
A17: Sistema operativo | B17: Windows 11 | C17: Equipo de pruebas | D17: Linux (contenedor de Render) | E17: Se declara; la API se prueba además en la versión publicada (E7)
A18: Lenguaje del backend | B18: Python 3.13 | C18: Ejecución de la API y de pytest | D18: Python 3.13 (.python-version) | E18: Ninguna
A19: Framework del backend | B19: FastAPI y Uvicorn | C19: API local y cliente de prueba | D19: FastAPI y Uvicorn | E19: Ninguna
A20: Base de datos | B20: SQLite (E1, E3, E6) y MySQL 8.4 (E4) | C20: Datos de prueba aislados de los de desarrollo | D20: MySQL 8.4 en Aiven con TLS | E20: SQLite no es el motor de producción; se compensa con la suite completa en MySQL (E4)
A21: Interfaz | B21: React 19, Vite 8 | C21: Navegador y pruebas de componentes | D21: React compilado servido por la API | E21: En E1 se usa Vite; en E7, la versión compilada
A22: Pruebas de interfaz | B22: Vitest 5, Node 24.22.1 | C22: Suite de 161 pruebas | D22: No aplica | E22: No aplica
A23: Pruebas del backend | B23: pytest, flake8, black | C23: Suite de 297 pruebas y revisión de estilo | D23: No aplica | E23: No aplica
A24: Pruebas de servicios | B24: Postman (colección de la Guía 7) | C24: Casos de servicios por rol | D24: No aplica | E24: No aplica
A25: Pruebas de carga | B25: Apache JMeter 5.6.3, Java Temurin 21 | C25: Carga básica de la API local | D25: No aplica | E25: La carga solo se ejecuta en local para no saturar servicios gratuitos
A26: Navegador | B26: Microsoft Edge con herramientas de desarrollo | C26: Emulación móvil y simulación de red desconectada | D26: Navegador del usuario final | E26: Se amplía con la emulación móvil
A27: Control de versiones | B27: Git y GitHub | C27: Una rama y una etiqueta por entrega | D27: No aplica | E27: No aplica
A29: 3. Ambiente de hardware
A30: Elemento | B30: Requisito | C30: Uso
A31: Equipo de pruebas | B31: Computador con Windows con memoria suficiente para ejecutar a la vez el servidor, el navegador y JMeter con interfaz gráfica | C31: E1 a E6
A32: Dispositivo móvil | B32: Teléfono Android (por ejemplo, Xiaomi 25062RN2DL usado en la Guía 8) o emulador de Android Studio | C32: E8
A33: Red | B33: Conexión a internet estable para E7; cortes simulados con las herramientas del navegador en E1 | C33: E1, E7
A34: Almacenamiento | B34: Espacio para el repositorio, bases de prueba, capturas y video de la ejecución; copia de respaldo de las evidencias en una unidad aparte | C34: Todos
A36: 4. Datos y usuarios de prueba
A37: Rol | B37: Correo de demostración | C37: Uso en las pruebas
A38: Propietario | B38: carlos.ramirez@pastoreando.co | C38: Lotes, alertas, firma, confirmación de pagos y reportes
A39: Arrendatario | B39: brayian.piedrahita@pastoreando.co | C39: Contratos, ganado, pagos, firma y costos
A40: Técnico | B40: laura.gomez@pastoreando.co | C40: Recomendaciones y pruebas de permisos
A41: Contador | B41: sandra.bedoya@pastoreando.co | C41: Costos, historial, pagos y reportes
A42: Carga inicial | B42: 8 usuarios, 4 lotes, 5 contratos y 12 hatos de ganado | C42: Se cargan solos cuando la base está vacía; el contrato 0001 tiene 26 cabezas a 85.000 por cabeza durante 6 meses
A43: Contraseñas y códigos | B43: No se escriben en este formato | C43: Se toman del archivo .env y del README del repositorio; JMeter recibe la contraseña con la propiedad -Jclave
A45: 5. Condiciones del entorno de producción y cómo se tratan en las pruebas
...

Sheet Trazabilidad
A1: Matriz de trazabilidad requisito · caso · resultado
A2: Los conteos se calculan desde la hoja «Casos de prueba» y se actualizan al diligenciar los resultados. La columna de casos asociados es la lista al momento de la entrega.
A4: Requisito | B4: Descripción | C4: Estado del requisito | D4: Casos diseñados | E4: Casos críticos | F4: Aprobados | G4: En seguimiento | H4: Rechazados | I4: Sin ejecutar | J4: Cobertura | K4: Casos asociados
A5: Acceso | B5: Acceso y sesión por roles | C5: Implementado | D5: =COUNTIF('Casos de prueba'!$D$5:$D$200,$A5) -> 9 | E5: =COUNTIFS('Casos de prueba'!$D$5:$D$200,$A5,'Casos de prueba'!$G$5:$G$200,"Crítica") -> 5 | F5: =COUNTIFS('Casos de prueba'!$D$5:$D$200,$A5,'Casos de prueba'!$Q$5:$Q$200,"Aprobado") -> 9 | G5: =COUNTIFS('Casos de prueba'!$D$5:$D$200,$A5,'Casos de prueba'!$Q$5:$Q$200,"En seguimiento") -> 0 | H5: =COUNTIFS('Casos de prueba'!$D$5:$D$200,$A5,'Casos de prueba'!$Q$5:$Q$200,"Rechazado") -> 0 | I5: =D5-F5-G5-H5 -> 0 | J5: =IF(D5=0,"Sin caso",IF(I5=D5,"Diseñado, sin ejecutar",IF(H5+G5>0,"Con novedades",IF(I5>0,"Parcial","Aprobado")))) -> Aprobado | K5: CP-008, CP-009, CP-010, CP-011, CP-012, CP-013, CP-014, CP-015, CP-016
A6: RF01 | B6: Costo por cabeza según el propósito del ganado | C6: Implementado | D6: =COUNTIF('Casos de prueba'!$D$5:$D$200,$A6) -> 5 | E6: =COUNTIFS('Casos de prueba'!$D$5:$D$200,$A6,'Casos de prueba'!$G$5:$G$200,"Crítica") -> 3 | F6: =COUNTIFS('Casos de prueba'!$D$5:$D$200,$A6,'Casos de prueba'!$Q$5:$Q$200,"Aprobado") -> 5 | G6: =COUNTIFS('Casos de prueba'!$D$5:$D$200,$A6,'Casos de prueba'!$Q$5:$Q$200,"En seguimiento") -> 0 | H6: =COUNTIFS('Casos de prueba'!$D$5:$D$200,$A6,'Casos de prueba'!$Q$5:$Q$200,"Rechazado") -> 0 | I6: =D6-F6-G6-H6 -> 0 | J6: =IF(D6=0,"Sin caso",IF(I6=D6,"Diseñado, sin ejecutar",IF(H6+G6>0,"Con novedades",IF(I6>0,"Parcial","Aprobado")))) -> Aprobado | K6: CP-001, CP-002, CP-003, CP-005, CP-006
A7: RF02 | B7: Desglose de costos por rubro | C7: Implementado | D7: =COUNTIF('Casos de prueba'!$D$5:$D$200,$A7) -> 2 | E7: =COUNTIFS('Casos de prueba'!$D$5:$D$200,$A7,'Casos de prueba'!$G$5:$G$200,"Crítica") -> 0 | F7: =COUNTIFS('Casos de prueba'!$D$5:$D$200,$A7,'Casos de prueba'!$Q$5:$Q$200,"Aprobado") -> 2 | G7: =COUNTIFS('Casos de prueba'!$D$5:$D$200,$A7,'Casos de prueba'!$Q$5:$Q$200,"En seguimiento") -> 0 | H7: =COUNTIFS('Casos de prueba'!$D$5:$D$200,$A7,'Casos de prueba'!$Q$5:$Q$200,"Rechazado") -> 0 | I7: =D7-F7-G7-H7 -> 0 | J7: =IF(D7=0,"Sin caso",IF(I7=D7,"Diseñado, sin ejecutar",IF(H7+G7>0,"Con novedades",IF(I7>0,"Parcial","Aprobado")))) -> Aprobado | K7: CP-004, CP-007
A8: RF03 | B8: Exportación de reportes a PDF y Excel | C8: Implementado | D8: =COUNTIF('Casos de prueba'!$D$5:$D$200,$A8) -> 2 | E8: =COUNTIFS('Casos de prueba'!$D$5:$D$200,$A8,'Casos de prueba'!$G$5:$G$200,"Crítica") -> 0 | F8: =COUNTIFS('Casos de prueba'!$D$5:$D$200,$A8,'Casos de prueba'!$Q$5:$Q$200,"Aprobado") -> 2 | G8: =COUNTIFS('Casos de prueba'!$D$5:$D$200,$A8,'Casos de prueba'!$Q$5:$Q$200,"En seguimiento") -> 0 | H8: =COUNTIFS('Casos de prueba'!$D$5:$D$200,$A8,'Casos de prueba'!$Q$5:$Q$200,"Rechazado") -> 0 | I8: =D8-F8-G8-H8 -> 0 | J8: =IF(D8=0,"Sin caso",IF(I8=D8,"Diseñado, sin ejecutar",IF(H8+G8>0,"Con novedades",IF(I8>0,"Parcial","Aprobado")))) -> Aprobado | K8: CP-042, CP-043
A9: RF04 | B9: Alerta de sobrecarga de un lote | C9: Implementado | D9: =COUNTIF('Casos de prueba'!$D$5:$D$200,$A9) -> 8 | E9: =COUNTIFS('Casos de prueba'!$D$5:$D$200,$A9,'Casos de prueba'!$G$5:$G$200,"Crítica") -> 3 | F9: =COUNTIFS('Casos de prueba'!$D$5:$D$200,$A9,'Casos de prueba'!$Q$5:$Q$200,"Aprobado") -> 8 | G9: =COUNTIFS('Casos de prueba'!$D$5:$D$200,$A9,'Casos de prueba'!$Q$5:$Q$200,"En seguimiento") -> 0 | H9: =COUNTIFS('Casos de prueba'!$D$5:$D$200,$A9,'Casos de prueba'!$Q$5:$Q$200,"Rechazado") -> 0 | I9: =D9-F9-G9-H9 -> 0 | J9: =IF(D9=0,"Sin caso",IF(I9=D9,"Diseñado, sin ejecutar",IF(H9+G9>0,"Con novedades",IF(I9>0,"Parcial","Aprobado")))) -> Aprobado | K9: CP-017, CP-018, CP-019, CP-020, CP-021, CP-022, CP-023, CP-024
A10: RF05 | B10: Contrato y firma digital | C10: Implementado | D10: =COUNTIF('Casos de prueba'!$D$5:$D$200,$A10) -> 10 | E10: =COUNTIFS('Casos de prueba'!$D$5:$D$200,$A10,'Casos de prueba'!$G$5:$G$200,"Crítica") -> 3 | F10: =COUNTIFS('Casos de prueba'!$D$5:$D$200,$A10,'Casos de prueba'!$Q$5:$Q$200,"Aprobado") -> 10 | G10: =COUNTIFS('Casos de prueba'!$D$5:$D$200,$A10,'Casos de prueba'!$Q$5:$Q$200,"En seguimiento") -> 0 | H10: =COUNTIFS('Casos de prueba'!$D$5:$D$200,$A10,'Casos de prueba'!$Q$5:$Q$200,"Rechazado") -> 0 | I10: =D10-F10-G10-H10 -> 0 | J10: =IF(D10=0,"Sin caso",IF(I10=D10,"Diseñado, sin ejecutar",IF(H10+G10>0,"Con novedades",IF(I10>0,"Parcial","Aprobado")))) -> Aprobado | K10: CP-025, CP-026, CP-027, CP-028, CP-029, CP-030, CP-031, CP-032, CP-033, CP-034
A11: RF06 | B11: Reporte de rentabilidad con margen del 20 % y recaudo | C11: Implementado | D11: =COUNTIF('Casos de prueba'!$D$5:$D$200,$A11) -> 4 | E11: =COUNTIFS('Casos de prueba'!$D$5:$D$200,$A11,'Casos de prueba'!$G$5:$G$200,"Crítica") -> 1 | F11: =COUNTIFS('Casos de prueba'!$D$5:$D$200,$A11,'Casos de prueba'!$Q$5:$Q$200,"Aprobado") -> 4 | G11: =COUNTIFS('Casos de prueba'!$D$5:$D$200,$A11,'Casos de prueba'!$Q$5:$Q$200,"En seguimiento") -> 0 | H11: =COUNTIFS('Casos de prueba'!$D$5:$D$200,$A11,'Casos de prueba'!$Q$5:$Q$200,"Rechazado") -> 0 | I11: =D11-F11-G11-H11 -> 0 | J11: =IF(D11=0,"Sin caso",IF(I11=D11,"Diseñado, sin ejecutar",IF(H11+G11>0,"Con novedades",IF(I11>0,"Parcial","Aprobado")))) -> Aprobado | K11: CP-035, CP-036, CP-037, CP-041
A12: RF07 | B12: Cálculo de áreas y parcelación de lotes | C12: Pendiente de construir | D12: =COUNTIF('Casos de prueba'!$D$5:$D$200,$A12) -> 1 | E12: =COUNTIFS('Casos de prueba'!$D$5:$D$200,$A12,'Casos de prueba'!$G$5:$G$200,"Crítica") -> 0 | F12: =COUNTIFS('Casos de prueba'!$D$5:$D$200,$A12,'Casos de prueba'!$Q$5:$Q$200,"Aprobado") -> 0 | G12: =COUNTIFS('Casos de prueba'!$D$5:$D$200,$A12,'Casos de prueba'!$Q$5:$Q$200,"En seguimiento") -> 0 | H12: =COUNTIFS('Casos de prueba'!$D$5:$D$200,$A12,'Casos de prueba'!$Q$5:$Q$200,"Rechazado") -> 0 | I12: =D12-F12-G12-H12 -> 1 | J12: =IF(D12=0,"Sin caso",IF(I12=D12,"Diseñado, sin ejecutar",IF(H12+G12>0,"Con novedades",IF(I12>0,"Parcial","Aprobado")))) -> Diseñado, sin ejecutar | K12: CP-056
A13: RF08 | B13: Alarmas configurables | C13: Pendiente de construir | D13: =COUNTIF('Casos de prueba'!$D$5:$D$200,$A13) -> 1 | E13: =COUNTIFS('Casos de prueba'!$D$5:$D$200,$A13,'Casos de prueba'!$G$5:$G$200,"Crítica") -> 0 | F13: =COUNTIFS('Casos de prueba'!$D$5:$D$200,$A13,'Casos de prueba'!$Q$5:$Q$200,"Aprobado") -> 0 | G13: =COUNTIFS('Casos de prueba'!$D$5:$D$200,$A13,'Casos de prueba'!$Q$5:$Q$200,"En seguimiento") -> 0 | H13: =COUNTIFS('Casos de prueba'!$D$5:$D$200,$A13,'Casos de prueba'!$Q$5:$Q$200,"Rechazado") -> 0 | I13: =D13-F13-G13-H13 -> 1 | J13: =IF(D13=0,"Sin caso",IF(I13=D13,"Diseñado, sin ejecutar",IF(H13+G13>0,"Con novedades",IF(I13>0,"Parcial","Aprobado")))) -> Diseñado, sin ejecutar | K13: CP-057
A14: RF09 | B14: Recomendaciones técnicas del zootecnista | C14: Implementado | D14: =COUNTIF('Casos de prueba'!$D$5:$D$200,$A14) -> 3 | E14: =COUNTIFS('Casos de prueba'!$D$5:$D$200,$A14,'Casos de prueba'!$G$5:$G$200,"Crítica") -> 0 | F14: =COUNTIFS('Casos de prueba'!$D$5:$D$200,$A14,'Casos de prueba'!$Q$5:$Q$200,"Aprobado") -> 3 | G14: =COUNTIFS('Casos de prueba'!$D$5:$D$200,$A14,'Casos de prueba'!$Q$5:$Q$200,"En seguimiento") -> 0 | H14: =COUNTIFS('Casos de prueba'!$D$5:$D$200,$A14,'Casos de prueba'!$Q$5:$Q$200,"Rechazado") -> 0 | I14: =D14-F14-G14-H14 -> 0 | J14: =IF(D14=0,"Sin caso",IF(I14=D14,"Diseñado, sin ejecutar",IF(H14+G14>0,"Con novedades",IF(I14>0,"Parcial","Aprobado")))) -> Aprobado | K14: CP-038, CP-039, CP-040
A15: RNF01 | B15: PWA con funcionamiento sin conexión | C15: Parcial | D15: =COUNTIF('Casos de prueba'!$D$5:$D$200,$A15) -> 5 | E15: =COUNTIFS('Casos de prueba'!$D$5:$D$200,$A15,'Casos de prueba'!$G$5:$G$200,"Crítica") -> 0 | F15: =COUNTIFS('Casos de prueba'!$D$5:$D$200,$A15,'Casos de prueba'!$Q$5:$Q$200,"Aprobado") -> 4 | G15: =COUNTIFS('Casos de prueba'!$D$5:$D$200,$A15,'Casos de prueba'!$Q$5:$Q$200,"En seguimiento") -> 0 | H15: =COUNTIFS('Casos de prueba'!$D$5:$D$200,$A15,'Casos de prueba'!$Q$5:$Q$200,"Rechazado") -> 0 | I15: =D15-F15-G15-H15 -> 1 | J15: =IF(D15=0,"Sin caso",IF(I15=D15,"Diseñado, sin ejecutar",IF(H15+G15>0,"Con novedades",IF(I15>0,"Parcial","Aprobado")))) -> Parcial | K15: CP-045, CP-046, CP-053, CP-054, CP-058
A16: RNF02 | B16: Copias de seguridad automáticas diarias | C16: Pendiente de construir | D16: =COUNTIF('Casos de prueba'!$D$5:$D$200,$A16) -> 1 | E16: =COUNTIFS('Casos de prueba'!$D$5:$D$200,$A16,'Casos de prueba'!$G$5:$G$200,"Crítica") -> 0 | F16: =COUNTIFS('Casos de prueba'!$D$5:$D$200,$A16,'Casos de prueba'!$Q$5:$Q$200,"Aprobado") -> 0 | G16: =COUNTIFS('Casos de prueba'!$D$5:$D$200,$A16,'Casos de prueba'!$Q$5:$Q$200,"En seguimiento") -> 0 | H16: =COUNTIFS('Casos de prueba'!$D$5:$D$200,$A16,'Casos de prueba'!$Q$5:$Q$200,"Rechazado") -> 0 | I16: =D16-F16-G16-H16 -> 1 | J16: =IF(D16=0,"Sin caso",IF(I16=D16,"Diseñado, sin ejecutar",IF(H16+G16>0,"Con novedades",IF(I16>0,"Parcial","Aprobado")))) -> Diseñado, sin ejecutar | K16: CP-059
A17: Transversal | B17: Validación de datos, paridad de motores, rendimiento y usabilidad móvil | C17: Implementado | D17: =COUNTIF('Casos de prueba'!$D$5:$D$200,$A17) -> 8 | E17: =COUNTIFS('Casos de prueba'!$D$5:$D$200,$A17,'Casos de prueba'!$G$5:$G$200,"Crítica") -> 0 | F17: =COUNTIFS('Casos de prueba'!$D$5:$D$200,$A17,'Casos de prueba'!$Q$5:$Q$200,"Aprobado") -> 8 | G17: =COUNTIFS('Casos de prueba'!$D$5:$D$200,$A17,'Casos de prueba'!$Q$5:$Q$200,"En seguimiento") -> 0 | H17: =COUNTIFS('Casos de prueba'!$D$5:$D$200,$A17,'Casos de prueba'!$Q$5:$Q$200,"Rechazado") -> 0 | I17: =D17-F17-G17-H17 -> 0 | J17: =IF(D17=0,"Sin caso",IF(I17=D17,"Diseñado, sin ejecutar",IF(H17+G17>0,"Con novedades",IF(I17>0,"Parcial","Aprobado")))) -> Aprobado | K17: CP-044, CP-047, CP-048, CP-049, CP-050, CP-051, CP-052, CP-055
A18: Total | D18: =SUM(D5:D17) -> 59 | E18: =SUM(E5:E17) -> 15 | F18: =SUM(F5:F17) -> 55 | G18: =SUM(G5:G17) -> 0 | H18: =SUM(H5:H17) -> 0 | I18: =SUM(I5:I17) -> 4
A20: Requisitos sin ningún caso | D20: =COUNTIF(D5:D17,0) -> 0

Sheet Listas
A1: Resultado | B1: Severidad | C1: Prioridad | D1: Tipo de prueba | E1: Herramienta | F1: Ambiente | G1: Requisito
A2: Aprobado | B2: Alta | C2: Crítica | D2: Funcional | E2: pytest | F2: E1 · Web: Edge en Windows, interfaz Vite (localhost:5173) y API local con SQLite de pruebas | G2: Acceso
A3: En seguimiento | B3: Media | C3: Alta | D3: Unitaria | E3: Vitest | F3: E2 · Web móvil: Edge con emulación iPhone 16 (393 × 852) sobre la API local con SQLite | G3: RF01
A4: Rechazado | B4: Baja | C4: Media | D4: Integración | E4: JUnit | F4: E3 · Backend: pytest con Python 3.13 y SQLite temporal por prueba | G4: RF02
B5: No aplica | D5: Carga y rendimiento | E5: Postman | F5: E4 · Backend: pytest contra MySQL 8.4 local (base pastoreando_prueba) | G5: RF03
D6: Seguridad | E6: Apache JMeter | F6: E5 · Interfaz: Vitest 5 (jsdom) sobre Node 24 | G6: RF04
D7: Usabilidad | E7: Manual (Edge) | F7: E6 · API: Postman y Apache JMeter 5.6.3 contra la API local con SQLite de pruebas | G7: RF05
D8: Regresión | E8: Manual (dispositivo Android) | F8: E7 · Revisión: versión publicada en Render con MySQL 8.4 en Aiven (solo lectura) | G8: RF06
E9: Manual (consola y mysqldump) | F9: E8 · Android: JUnit y aplicación en emulador o dispositivo | G9: RF07
G10: RF08
G11: RF09
G12: RNF01
G13: RNF02
G14: Transversal
